<?xml version="1.0" ?>
<!-- =================================================================================== -->
<!-- |    This document was autogenerated by xacro from src/youbot_description/urdf/youbot_arm.urdf.xacro | -->
<!-- |    EDITING THIS FILE BY HAND IS NOT RECOMMENDED                                 | -->
<!-- =================================================================================== -->
<robot name="youbot_arm">
  <material name="black">
    <color rgba="0 0 0 1"/>
  </material>
  <material name="orange">
    <color rgba="1 0.5 0 1"/>
  </material>
  <material name="red">
    <color rgba="1 0 0 1"/>
  </material>
  <material name="green">
    <color rgba="0 1 0 1"/>
  </material>
  <material name="blue">
    <color rgba="0 0 1 1"/>
  </material>
  <material name="yellow">
    <color rgba="1 1 0 1"/>
  </material>
  <material name="white">
    <color rgba="1 1 1 1"/>
  </material>
  <link name="arm_base_part1">
    <visual>
      <geometry>
        <box size="0.085 0.113 0.057"/>
      </geometry>
      <origin rpy="0 0 0" xyz="0 -0.0565 0.0285"/>
      <material name="black"/>
    </visual>
  </link>
  <link name="arm_base_part2">
    <visual>
      <geometry>
        <cylinder length="0.067" radius="0.078"/>
      </geometry>
      <origin rpy="0 0 0" xyz="0 0 0.0335"/>
      <material name="black"/>
    </visual>
  </link>
  <joint name="arm_base_fixed" type="fixed">
    <parent link="arm_base_part1"/>
    <child link="arm_base_part2"/>
    <origin rpy="0 0 0" xyz="0 0 0"/>
  </joint>
  <joint name="joint1" type="revolute">
    <parent link="arm_base_part1"/>
    <child link="link1_part1"/>
    <origin rpy="0 0 1.57075" xyz="0 0 0.067"/>
    <axis xyz="0 0 1"/>
    <limit effort="0.5" lower="-2.95" upper="2.95" velocity="0.5"/>
  </joint>
  <link name="link1_part1">
    <visual>
      <geometry>
        <cylinder length="0.032" radius="0.078"/>
      </geometry>
      <origin rpy="0 0 0" xyz="0 0 0.016"/>
      <material name="orange"/>
    </visual>
  </link>
  <link name="link1_part2">
    <visual>
      <geometry>
        <cylinder length="0.045" radius="0.037"/>
      </geometry>
      <origin rpy="1.57075 0 0" xyz="0 0.0225 0"/>
      <material name="orange"/>
    </visual>
  </link>
  <joint name="link1_fixed" type="fixed">
    <parent link="link1_part1"/>
    <child link="link1_part2"/>
    <origin rpy="0 0 0" xyz="0.033 0 0.069"/>
  </joint>
  <joint name="joint2" type="revolute">
    <parent link="link1_part1"/>
    <child link="link2_part1"/>
    <origin rpy="0 0 -1.57079" xyz="0.033 0 0.069"/>
    <axis xyz="1 0 0"/>
    <limit effort="0.5" lower="-1.57" upper="1.31" velocity="0.5"/>
  </joint>
  <link name="link2_part1">
    <visual>
      <geometry>
        <cylinder length="0.04" radius="0.037"/>
      </geometry>
      <origin rpy="0 1.57075 0" xyz="0.02 0 0"/>
      <material name="black"/>
    </visual>
  </link>
  <joint name="link2_fixed1" type="fixed">
    <parent link="link2_part1"/>
    <child link="link2_part2"/>
    <origin rpy="0 0 0" xyz="0 0 0"/>
  </joint>
  <link name="link2_part2">
    <visual>
      <geometry>
        <box size="0.03 0.04 0.155"/>
      </geometry>
      <origin rpy="0 0 0" xyz="0.015 0 0.0775"/>
      <material name="black"/>
    </visual>
  </link>
  <joint name="link2_fixed2" type="fixed">
    <parent link="link2_part2"/>
    <child link="link2_part3"/>
    <origin rpy="0 0 0" xyz="0 0 0.155"/>
  </joint>
  <link name="link2_part3">
    <visual>
      <geometry>
        <cylinder length="0.03" radius="0.03"/>
      </geometry>
      <origin rpy="0 1.57075 0" xyz="0.015 0 0"/>
      <material name="black"/>
    </visual>
  </link>
  <joint name="joint3" type="revolute">
    <parent link="link2_part1"/>
    <child link="link3_part1"/>
    <origin rpy="0 0 0" xyz="0 0 0.155"/>
    <axis xyz="1 0 0"/>
    <limit effort="0.5" lower="-2.28" upper="2.28" velocity="0.5"/>
  </joint>
  <link name="link3_part1">
    <visual>
      <geometry>
        <cylinder length="0.03" radius="0.03"/>
      </geometry>
      <origin rpy="0 1.57075 0" xyz="-0.015 0 0"/>
      <material name="orange"/>
    </visual>
  </link>
  <joint name="link3_fixed1" type="fixed">
    <parent link="link3_part1"/>
    <child link="link3_part2"/>
    <origin rpy="0 0 0" xyz="0 0 0"/>
  </joint>
  <link name="link3_part2">
    <visual>
      <geometry>
        <box size="0.02 0.03 0.13483"/>
      </geometry>
      <origin rpy="0 0 0" xyz="-0.01 0 0.067415"/>
      <material name="orange"/>
    </visual>
  </link>
  <joint name="link3_fixed2" type="fixed">
    <parent link="link3_part2"/>
    <child link="link3_part3"/>
    <origin rpy="0 0 0" xyz="0 0 0.13483"/>
  </joint>
  <link name="link3_part3">
    <visual>
      <geometry>
        <cylinder length="0.02" radius="0.025"/>
      </geometry>
      <origin rpy="0 1.57075 0" xyz="-0.01 0 0"/>
      <material name="orange"/>
    </visual>
  </link>
  <joint name="joint4" type="revolute">
    <parent link="link3_part1"/>
    <child link="link4_part1"/>
    <origin rpy="0 0 0" xyz="0 0 0.13483"/>
    <axis xyz="1 0 0"/>
    <limit effort="0.5" lower="-1.78" upper="1.78" velocity="0.5"/>
  </joint>
  <link name="link4_part1">
    <visual>
      <geometry>
        <cylinder length="0.02" radius="0.025"/>
      </geometry>
      <origin rpy="0 1.57075 0" xyz="0.01 0 0"/>
      <material name="orange"/>
    </visual>
  </link>
  <link name="link4_part2">
    <visual>
      <geometry>
        <box size="0.06 0.04 0.059"/>
      </geometry>
      <origin rpy="0 0 0" xyz="0 0 0.0295"/>
      <material name="orange"/>
    </visual>
  </link>
  <joint name="link4_fixed" type="fixed">
    <parent link="link4_part1"/>
    <child link="link4_part2"/>
    <origin rpy="0 0 0" xyz="0 0 0.025"/>
  </joint>
  <joint name="joint5" type="revolute">
    <parent link="link4_part1"/>
    <child link="link5_part1"/>
    <origin rpy="0 0 0" xyz="0 0 0.084"/>
    <axis xyz="0 0 1"/>
    <limit effort="0.5" lower="-1.57" upper="1.57" velocity="0.5"/>
  </joint>
  <link name="link5_part1">
    <visual>
      <geometry>
        <box size="0.06 0.04 0.08465"/>
      </geometry>
      <origin rpy="0 0 0" xyz="0 0 0.042325"/>
      <material name="black"/>
    </visual>
  </link>
  <joint name="link5_fixed1" type="fixed">
    <parent link="link5_part1"/>
    <child link="link5_part2"/>
    <origin rpy="0 0 0" xyz="0.02 0 0.06"/>
  </joint>
  <link name="link5_part2">
    <visual>
      <geometry>
        <box size="0.01 0.01 0.05"/>
      </geometry>
      <origin rpy="0 0 0" xyz="0 0 0.025"/>
      <material name="black"/>
    </visual>
  </link>
  <joint name="link5_fixed2" type="fixed">
    <parent link="link5_part1"/>
    <child link="link5_part3"/>
    <origin rpy="0 0 0" xyz="-0.02 0 0.06"/>
  </joint>
  <link name="link5_part3">
    <visual>
      <geometry>
        <box size="0.01 0.01 0.05"/>
      </geometry>
      <origin rpy="0 0 0" xyz="0 0 0.025"/>
      <material name="black"/>
    </visual>
  </link>
</robot>
