<?xml version="1.0"?>
<robot name="youbot" xmlns:xacro="http://www.ros.org/wiki/xacro">

  <xacro:include filename="youbot_arm.urdf.xacro" />

  <link name="base_link">
    <visual>
      <geometry>
        <box size="0.233 0.57 0.094"/>
      </geometry>
      <origin rpy="0 0 0" xyz="0 0 0.067"/>
      <material name="white"/>
    </visual>
  </link>

  <joint name="rf_motor" type="continuous">
    <parent link="base_link"/>
    <child link="rf_wheel"/>
    <origin xyz="0.117 0.228 0.047"/>    
    <axis xyz="1 0 0"/>
  </joint>

  <link name="rf_wheel">
    <visual>
      <geometry>
        <cylinder length="0.073" radius="0.047"/>
      </geometry>
      <origin rpy="0 1.57075 0" xyz="0.0465 0 0"/>
      <material name="black"/>
    </visual>
  </link>

  <joint name="lf_motor" type="continuous">
    <parent link="base_link"/>
    <child link="lf_wheel"/>
    <origin xyz="-0.117 0.228 0.047"/>    
    <axis xyz="1 0 0"/>
  </joint>

  <link name="lf_wheel">
    <visual>
      <geometry>
        <cylinder length="0.073" radius="0.047"/>
      </geometry>
      <origin rpy="0 1.57075 0" xyz="-0.0465 0 0"/>
      <material name="black"/>
    </visual>
  </link>

  <joint name="rr_motor" type="continuous">
    <parent link="base_link"/>
    <child link="rr_wheel"/>
    <origin xyz="0.117 -0.228 0.047"/>    
    <axis xyz="1 0 0"/>
  </joint>

  <link name="rr_wheel">
    <visual>
      <geometry>
        <cylinder length="0.073" radius="0.047"/>
      </geometry>
      <origin rpy="0 1.57075 0" xyz="0.0465 0 0"/>
      <material name="black"/>
    </visual>
  </link>

  <joint name="lr_motor" type="continuous">
    <parent link="base_link"/>
    <child link="lr_wheel"/>
    <origin xyz="-0.117 -0.228 0.047"/>    
    <axis xyz="1 0 0"/>
  </joint>

  <link name="lr_wheel">
    <visual>
      <geometry>
        <cylinder length="0.073" radius="0.047"/>
      </geometry>
      <origin rpy="0 1.57075 0" xyz="-0.0465 0 0"/>
      <material name="black"/>
    </visual>
  </link>

  <joint name="youbot_base" type="fixed">
    <parent link="base_link"/>
    <child link="arm_base_part1"/>
    <origin xyz="0 0.166 0.1" rpy="0 0 0"/>
  </joint>
  
</robot>