<?xml version="1.0"?>
<robot name="youbot_arm" xmlns:xacro="http://www.ros.org/wiki/xacro">

  <xacro:include filename="colors.urdf.xacro"/>

  <xacro:include filename="arm_base.urdf.xacro"/>

  <joint name="joint1" type="revolute">
      <parent link="arm_base_part1"/>
      <child link="link1_part1"/>
      <origin xyz="0 0 0.067" rpy="0 0 1.57075"/>
      <axis xyz="0 0 1"/>
      <limit lower="-2.95" upper="2.95" effort="0.5" velocity="0.5"/>
  </joint>

  <xacro:include filename="link1.urdf.xacro"/>

  <joint name="joint2" type="revolute">
      <parent link="link1_part1"/>
      <child link="link2_part1"/>
      <origin xyz="0.033 0 0.069" rpy="0 0 -1.57079"/>
      <axis xyz="1 0 0"/>
      <limit lower="-1.57" upper="1.31" effort="0.5" velocity="0.5"/>
  </joint>

  <xacro:include filename="link2.urdf.xacro"/>

  <joint name="joint3" type="revolute">
      <parent link="link2_part1"/>
      <child link="link3_part1"/>
      <origin xyz="0 0 0.155" rpy="0 0 0"/>
      <axis xyz="1 0 0"/>
      <limit lower="-2.28" upper="2.28" effort="0.5" velocity="0.5"/>
  </joint>

  <xacro:include filename="link3.urdf.xacro"/>

  <joint name="joint4" type="revolute">
      <parent link="link3_part1"/>
      <child link="link4_part1"/>
      <origin xyz="0 0 0.13483" rpy="0 0 0"/>
      <axis xyz="1 0 0"/>
      <limit lower="-1.78" upper="1.78" effort="0.5" velocity="0.5"/>
  </joint>

  <xacro:include filename="link4.urdf.xacro"/>

  <joint name="joint5" type="revolute">
      <parent link="link4_part1"/>
      <child link="link5_part1"/>
      <origin xyz="0 0 0.084" rpy="0 0 0"/>
      <axis xyz="0 0 1"/>
      <limit lower="-1.57" upper="1.57" effort="0.5" velocity="0.5"/>
  </joint>

  <xacro:include filename="link5.urdf.xacro"/>

</robot>